Workbook

Sheet Executive Dashboard
A1: INDAMART B2B MARKETPLACE — EXECUTIVE QA TESTING DASHBOARD
B3: TOTAL TEST CASES | D3: EXECUTION RATE | F3: PASS RATE
B4: =COUNTA('Test Cases'!A2:A121) | D4: =Metrics!E11 | F4: =Metrics!E12
A6: 1. PROJECT & EXECUTIVE SCOPE DETAILS
A7: Project Name | B7: IndiaMART B2B Marketplace & Seller Ecosystem Comprehensive QA
A8: Application Type | B8: Multi-Vendor B2B E-Commerce Marketplace
A9: Testing Methodology | B9: Functional Verification, Integration Testing, Defect Tracking & Math Metrics Analysis
A10: Prepared By | B10: Senior QA Lead / QA Automation Architect
A11: Execution Date | B11: September 24, 2026
A12: Document Edition | B12: 4.0 (Master Clarity & Executive Edition)
A14: 2. WORKBOOK CLARITY & TAB NAVIGATION GUIDE
A15: Tab Name | B15: Purpose & Description | E15: Key Elements / Highlights
A16: Test Metrics Problems | B16: Step-by-step problem statements, formulas, and verified solutions for all 9 IndiaMART metrics exercises | E16: Problem 1 through 9: Requirement Coverage, Execution %, Pass/Fail Rate, Defect Density, Mean & Median Latencies
A17: Metrics | B17: Contains all QA math formulas, metrics evaluations, and defect distribution tables | E17: Test Coverage (100%), Pass Rate (98.3%), Defect Density (0.0125/KLOC)
A18: Module Summary | B18: Summarizes test execution progress across all 10 core B2B modules | E18: TC counts, Pass/Fail counts, and Pass % breakdown per module
A19: Test Cases | B19: Comprehensive log of all 120 executed test cases with steps and actual results | E19: 118 Passed, 2 Failed (TC_039 & TC_070) with clear status tags
A20: Requirements | B20: Traceability matrix mapping functional requirements to executed test cases | E20: R01 through R14 mapping verification and coverage tracking
A21: Defects | B21: Bug tracker logging open defects linked to failed test cases | E21: DEF-001 (Admin Moderation) & DEF-002 (BuyLead Disputes) details
A22: Response Times | B22: Performance page loading latency test sample measurements | E22: 5 consecutive catalog loading tests feeding Mean and Median formulas

Sheet Test Metrics Problems
A1: INDAMART — TEST METRICS PROBLEMS & STEP-BY-STEP CALCULATIONS
A3: India MART – Test Metrics Problems and Answers
A5: Problem 1: Requirement Test Coverage
A6: India MART engineering team is releasing an updated GST Invoicing & Lead Export Module with 400 total functional requirements. The QA team executed manual and automated tests for 356 requirements. Calculate the Test Coverage percentage.
A7: Formula: | B7: Test Coverage = (Requirements Tested / Total Requirements) x 100
A8: Requirements Tested | B8: 356
A9: Total Requirements | B9: 400
A10: Test Coverage = | B10: =B8/B9*100 | C10: %
A13: Problem 2: Test Execution Percentage
A14: During the testing cycle for the India MART Seller Mobile App (v12.0), a regression test suite of 1,200 test cases was created. By day 4, the QA team completed execution of 1,050 test cases. Calculate the Test Execution Percentage.
A15: Formula: | B15: Test Execution % = (Executed Test Cases / Total Test Cases) x 100
A16: Executed Test Cases | B16: 1050
A17: Total Test Cases | B17: 1200
A18: Test Execution % = | B18: =B16/B17*100 | C18: %
A21: Problem 3: Pass Rate and Fail Rate
A22: India MART executed 800 automated API test cases on its Seller Payment Gateway (UPI/Net Banking). Out of these, 712 passed and 88 failed due to timeout issues. Calculate the Pass Rate and Fail Rate.
A23: Formulas: | B23: Pass Rate = (Passed / Executed) x 100 | Fail Rate = (Failed / Executed) x 100
A24: Passed Test Cases | B24: 712
A25: Failed Test Cases | B25: 88
A26: Executed Test Cases | B26: 800
A27: Pass Rate = | B27: =B24/B26*100 | C27: %
A28: Fail Rate = | B28: =B25/B26*100 | C28: %
A31: Problem 4: Defect Density
A32: IndiaMART's Buyer Inquiry Matching Engine was refactored with 160,000 Lines of Code (LOC). System integration testing revealed 240 defects. Calculate the Defect Density per KLOC.
A33: Formulas: | B33: KLOC = Total LOC / 1,000 | Defect Density = Total Defects / KLOC
A34: Total Lines of Code (LOC) | B34: 160000
A35: Total Defects | B35: 240
A36: KLOC = | B36: =B34/1000 | C36: KLOC
A37: Defect Density = | B37: =B35/B36 | C37: defects/KLOC
A40: Problem 5: Mean (Average Response Time)
A41: Performance engineers test the response time of IndiaMART Search API across 6 consecutive requests. Recorded values: 180 ms, 210 ms, 195 ms, 205 ms, 220 ms, and 190 ms. Calculate the Mean response time.
A42: Formula: | B42: Mean = Sum of Values / Total Number of Values
A43: Response Time (ms) | B43: 180
A44: Response Time (ms) | B44: 210
A45: Response Time (ms) | B45: 195
A46: Response Time (ms) | B46: 205
A47: Response Time (ms) | B47: 220
A48: Response Time (ms) | B48: 190
A49: Mean Response Time = | B49: =AVERAGE(B43:B48) | C49: ms
A52: Problem 6: Median (Odd Sample Count)
...

Sheet Metrics
A1: IndiaMART Marketplace — Manual Testing and Test Metrics Analysis
A4: Input
A5: Software size (LOC) | B5: 160000 | C5: Problem statement LOC for Buyer Inquiry Matching Engine (160,000 LOC).
A6: KLOC | B6: =B5/1000
A8: Metrics and evaluations
A9: Metric | B9: Formula | C9: Value 1 | D9: Value 2 | E9: Result | F9: Evaluation & Clarity Explanation
A10: 1. Test Coverage | B10: (Requirements tested / Total requirements) x 100 | C10: =COUNTIF(Requirements!F2:F15, "Yes") | D10: =COUNTA(Requirements!A2:A15) | E10: =C10/D10 | F10: 100% of the 14 mapped requirements are tested by at least one test case.
A11: 2. Test Execution % | B11: (Executed / Total test cases) x 100 | C11: =COUNTA('Test Cases'!F2:F121) | D11: =COUNTA('Test Cases'!A2:A121) | E11: =C11/D11 | F11: All 120 planned regression & functional test cases were executed.
A12: 3. Pass Rate | B12: (Passed / Executed) x 100 | C12: =COUNTIF('Test Cases'!F2:F121, "Pass") | D12: =COUNTA('Test Cases'!F2:F121) | E12: =C12/D12 | F12: 118 out of 120 executed test cases passed successfully (98.33%).
A13: 4. Fail Rate | B13: (Failed / Executed) x 100 | C13: =COUNTIF('Test Cases'!F2:F121, "Fail") | D13: =COUNTA('Test Cases'!F2:F121) | E13: =C13/D13 | F13: 2 out of 120 test cases failed (1.67%) due to moderation and lead refund defects.
A14: 5. Defect Density | B14: Unique defects / KLOC | C14: =COUNTA(Defects!A2:A3) | D14: =B6 | E14: =C14/D14 | F14: Defect density is 0.0125 defects per KLOC (2 defects across 160 KLOC).
A15: 6. Mean (page loading) | B15: Sum of values / Number of values | C15: =SUM('Response Times'!B2:B6) | D15: =COUNT('Response Times'!B2:B6) | E15: =AVERAGE('Response Times'!B2:B6) | F15: The average loading time for Supplier Product Catalog Page across 5 runs.
A16: 7. Median (page loading) | B16: Middle value of sorted data | C16: Sorted: 1.8, 2.1, 2.8, 3.2, 4.5 | D16: =COUNT('Response Times'!B2:B6) | E16: =MEDIAN('Response Times'!B2:B6) | F16: The middle catalog page loading time is 2.80 seconds (3rd sample).
A17: 8. Mean vs Median | B17: Mean - Median | C17: =E15 | D17: =E16 | E17: =E15-E16 | F17: Mean (2.88s) is higher than Median (2.80s) due to a 4.5s peak load outlier.
A18: 9. Critical Defect % | B18: (Critical defects / Total defects) x 100 | C18: =COUNTIF(Defects!E2:E3, "High") | D18: =COUNTA(Defects!A2:A3) | E18: =C18/D18 | F18: All 2 logged defects are High severity and must be remediated prior to release.
A20: 10. Defect Distribution
A21: Severity | B21: Calculation | C21: Defects | D21: Total defects | E21: Distribution | F21: Evaluation & Action Required
A22: Critical | B22: =COUNTIF(Defects!E2:E3, "Critical") | C22: =COUNTIF(Defects!E2:E3, "Critical") | D22: =COUNTA(Defects!A2:A3) | E22: =C22/D22 | F22: No critical blockers reported.
A23: High | B23: =COUNTIF(Defects!E2:E3, "High") | C23: =COUNTIF(Defects!E2:E3, "High") | D23: =COUNTA(Defects!A2:A3) | E23: =C23/D23 | F23: 2 High severity defects (100% of open bugs). Remediation required.
A24: Medium | B24: =COUNTIF(Defects!E2:E3, "Medium") | C24: =COUNTIF(Defects!E2:E3, "Medium") | D24: =COUNTA(Defects!A2:A3) | E24: =C24/D24 | F24: None reported.
A25: Low | B25: =COUNTIF(Defects!E2:E3, "Low") | C25: =COUNTIF(Defects!E2:E3, "Low") | D25: =COUNTA(Defects!A2:A3) | E25: =C25/D25 | F25: None reported.
A26: Total | B26: - | C26: =SUM(C22:C25) | D26: =C26/D26 | E26: =C26/D26 | F26: 2 Total Open Defects
A28: 11. Final Metrics Summary
A29: Metric | B29: Result
A30: Test Coverage | B30: =E10
A31: Test Execution % | B31: =E11
A32: Pass Rate | B32: =E12
A33: Fail Rate | B33: =E13
A34: Unique Defects | B34: =COUNTA(Defects!A2:A3)
A35: Defect Density | B35: =E14
A36: Mean Page Loading Time | B36: =E15
A37: Median Page Loading Time | B37: =E16
A38: Critical Defect % | B38: =E18
A39: High Severity Defects | B39: =C23

Sheet Module Summary
A1: Module ID & Description | B1: Total TCs | C1: Passed TCs | D1: Failed TCs | E1: Blocked / Not Run | F1: Pass Rate %
A2: 1. Seller Onboarding & KYC | B2: =COUNTIF('Test Cases'!B:B, A2) | C2: =COUNTIFS('Test Cases'!B:B, A2, 'Test Cases'!F:F, "Pass") | D2: =COUNTIFS('Test Cases'!B:B, A2, 'Test Cases'!F:F, "Fail") | E2: 0 | F2: =C2/B2
A3: 2. Seller Profile & Business Settings | B3: =COUNTIF('Test Cases'!B:B, A3) | C3: =COUNTIFS('Test Cases'!B:B, A3, 'Test Cases'!F:F, "Pass") | D3: =COUNTIFS('Test Cases'!B:B, A3, 'Test Cases'!F:F, "Fail") | E3: 0 | F3: =C3/B3
A4: 3. Catalog & Product Management | B4: =COUNTIF('Test Cases'!B:B, A4) | C4: =COUNTIFS('Test Cases'!B:B, A4, 'Test Cases'!F:F, "Pass") | D4: =COUNTIFS('Test Cases'!B:B, A4, 'Test Cases'!F:F, "Fail") | E4: 0 | F4: =C4/B4
A5: 4. Search, Filters & RFQ Quotes | B5: =COUNTIF('Test Cases'!B:B, A5) | C5: =COUNTIFS('Test Cases'!B:B, A5, 'Test Cases'!F:F, "Pass") | D5: =COUNTIFS('Test Cases'!B:B, A5, 'Test Cases'!F:F, "Fail") | E5: 0 | F5: =C5/B5
A6: 5. Lead Management & CRM | B6: =COUNTIF('Test Cases'!B:B, A6) | C6: =COUNTIFS('Test Cases'!B:B, A6, 'Test Cases'!F:F, "Pass") | D6: =COUNTIFS('Test Cases'!B:B, A6, 'Test Cases'!F:F, "Fail") | E6: 0 | F6: =C6/B6
A7: 6. Payments, Escrow & Invoicing | B7: =COUNTIF('Test Cases'!B:B, A7) | C7: =COUNTIFS('Test Cases'!B:B, A7, 'Test Cases'!F:F, "Pass") | D7: =COUNTIFS('Test Cases'!B:B, A7, 'Test Cases'!F:F, "Fail") | E7: 0 | F7: =C7/B7
A8: 7. Mobile App & Real-Time Push | B8: =COUNTIF('Test Cases'!B:B, A8) | C8: =COUNTIFS('Test Cases'!B:B, A8, 'Test Cases'!F:F, "Pass") | D8: =COUNTIFS('Test Cases'!B:B, A8, 'Test Cases'!F:F, "Fail") | E8: 0 | F8: =C8/B8
A9: 8. Security, Session & Compliance | B9: =COUNTIF('Test Cases'!B:B, A9) | C9: =COUNTIFS('Test Cases'!B:B, A9, 'Test Cases'!F:F, "Pass") | D9: =COUNTIFS('Test Cases'!B:B, A9, 'Test Cases'!F:F, "Fail") | E9: 0 | F9: =C9/B9
A10: 9. Analytics & Paid Subscriptions | B10: =COUNTIF('Test Cases'!B:B, A10) | C10: =COUNTIFS('Test Cases'!B:B, A10, 'Test Cases'!F:F, "Pass") | D10: =COUNTIFS('Test Cases'!B:B, A10, 'Test Cases'!F:F, "Fail") | E10: 0 | F10: =C10/B10
A11: 10. Platform, UI & Performance | B11: =COUNTIF('Test Cases'!B:B, A11) | C11: =COUNTIFS('Test Cases'!B:B, A11, 'Test Cases'!F:F, "Pass") | D11: =COUNTIFS('Test Cases'!B:B, A11, 'Test Cases'!F:F, "Fail") | E11: 0 | F11: =C11/B11
A12: Total Summary | B12: =SUM(B2:B11) | C12: =SUM(C2:C11) | D12: =SUM(D2:D11) | E12: =SUM(E2:E11) | F12: =C12/B12

Sheet Test Cases
A1: TC ID | B1: Module Name | C1: Req ID | D1: Test Case Scenario | E1: Expected Result | F1: Actual Result | G1: Status | H1: Linked Defect ID
A2: TC_001 | B2: 1. Seller Onboarding & KYC | C2: R01 | D2: Register seller with valid Indian mobile number | E2: Account created; redirected to seller setup wizard. | F2: As expected | G2: Pass
A3: TC_002 | B3: 1. Seller Onboarding & KYC | C3: R01 | D3: Register seller with invalid mobile number | E3: Error: "Please enter a valid 10-digit mobile number". | F3: As expected | G3: Pass
A4: TC_003 | B4: 1. Seller Onboarding & KYC | C4: R01 | D4: Resend OTP limit verification | E4: System blocks further OTP requests for 15 minutes. | F4: As expected | G4: Pass
A5: TC_004 | B5: 1. Seller Onboarding & KYC | C5: R01 | D5: Valid 15-digit GSTIN verification | E5: GST details auto-populated from GSTN database; Verified badge displayed. | F5: As expected | G5: Pass
A6: TC_005 | B6: 1. Seller Onboarding & KYC | C6: R01 | D6: Invalid GSTIN format validation | E6: Inline validation error: "Invalid GSTIN format". | F6: As expected | G6: Pass
A7: TC_006 | B7: 1. Seller Onboarding & KYC | C7: R01 | D7: GSTIN already linked to another account | E7: System blocks submission: "GSTIN already linked with another account". | F7: As expected | G7: Pass
A8: TC_007 | B8: 1. Seller Onboarding & KYC | C8: R01 | D8: Upload valid Business PAN | E8: Image uploaded successfully; status set to "Pending Verification". | F8: As expected | G8: Pass
A9: TC_008 | B9: 1. Seller Onboarding & KYC | C9: R01 | D9: Upload unsupported file type for PAN | E9: Validation error: "Only JPG, PNG, and PDF formats supported". | F9: As expected | G9: Pass
A10: TC_009 | B10: 2. Seller Profile & Business Settings | C10: R02 | D10: Add company name with special characters | E10: Input sanitized or error displayed for invalid special characters. | F10: As expected | G10: Pass
A11: TC_010 | B11: 2. Seller Profile & Business Settings | C11: R02 | D11: Add official company business address | E11: City and State auto-populated as Hyderabad, Telangana. | F11: As expected | G11: Pass
A12: TC_011 | B12: 2. Seller Profile & Business Settings | C12: R02 | D12: PIN Code & City auto-mapping check | E12: Validation message: "Invalid PIN Code". | F12: As expected | G12: Pass
A13: TC_012 | B13: 2. Seller Profile & Business Settings | C13: R02 | D13: Upload company logo (within size limit) | E13: Logo displays on public seller page and catalog. | F13: As expected | G13: Pass
... A39: TC_038 | B39: 3. Catalog & Product Management | C39: R03 | D39: Search engine optimization (SEO) tag addition | E39: Tags attached to metadata for search indexing. | F39: As expected | G39: Pass
A40: TC_039 | B40: 3. Catalog & Product Management | C40: R03 | D40: Product approval workflow (Admin Moderation) | E40: Flagged by automated moderation system; status set to "Rejected". | F40: Behavior mismatched; issue logged | G40: Fail | H40: DEF-001
A41: TC_040 | B41: 3. Catalog & Product Management | C41: R03 | D41: Export full product catalog to PDF/Excel | E41: Downloadable catalog file generated with prices and specifications. | F41: As expected | G41: Pass
A42: TC_041 | B42: 4. Search, Filters & RFQ Quotes | C42: R03 | D42: Search product by exact keyword | E42: Relevant solar panel listings displayed sorted by rank. | F42: As expected | G42: Pass
A43: TC_042 | B43: 4. Search, Filters & RFQ Quotes | C43: R03 | D43: Search product with typo/misspelling | E43: Auto-correct triggers: "Showing results for Solar Panel". | F43: As expected | G43: Pass
A44: TC_043 | B44: 4. Search, Filters & RFQ Quotes | C44: R03 | D44: Filter search results by Location (City/State) | E44: Only Surat-based suppliers displayed. | F44: As expected | G44: Pass
A45: TC_044 | B45: 4. Search, Filters & RFQ Quotes | C45: R03 | D45: Filter search results by Verified Supplier badge | E45: Non-verified suppliers filtered out. | F45: As expected | G45: Pass
A46: TC_045 | B46: 4. Search, Filters & RFQ Quotes | C46: R03 | D46: Sort search results by Price: Low to High | E46: Results ordered in strictly ascending price sequence. | F46: As expected | G46: Pass
A47: TC_046 | B47: 4. Search, Filters & RFQ Quotes | C47: R03 | D47: Search non-existent product | E47: "No results found. Submit a BuyRequirement instead." displayed. | F47: As expected | G47: Pass
A48: TC_047 | B48: 4. Search, Filters & RFQ Quotes | C48: R04 | D48: Send single inquiry via "Get Best Price" button | E48: "Inquiry Sent Successfully" modal shown; SMS sent to buyer & seller. | F48: As expected | G48: Pass
A49: TC_048 | B49: 4. Search, Filters & RFQ Quotes | C49: R04 | D49: Send inquiry while logged in as buyer | E49: Pre-filled contact details displayed; inquiry sent in 1 click. | F49: As expected | G49: Pass
A50: TC_049 | B50: 4. Search, Filters & RFQ Quotes | C50: R04 | D50: Submit BuyRequirement form (Post Requirement) | E50: BuyLead generated and posted to IndiaMART Lead Matcher. | F50: As expected | G50: Pass
A51: TC_050 | B51: 4. Search, Filters & RFQ Quotes | C51: R04 | D51: Submit BuyRequirement with missing quantity | E51: Error: "Please specify required quantity". | F51: As expected | G51: Pass
A52: TC_051 | B52: 4. Search, Filters & RFQ Quotes | C52: R04 | D52: Attach technical PDF drawing to BuyRequirement | E52: Attachment uploaded and linked to the lead sent to sellers. | F52: As expected | G52: Pass
... A70: TC_069 | B70: 5. Lead Management & CRM | C70: R05 | D70: Reject irrelevant / invalid BuyLead | E70: Lead archived; matching algorithm adjusts future lead delivery. | F70: As expected | G70: Pass
A71: TC_070 | B71: 5. Lead Management & CRM | C71: R05 | D71: Claim BuyLead refund / credit point | E71: Dispute logged; lead credit refunded after automated verification. | F71: Behavior mismatched; issue logged | G71: Fail | H71: DEF-002
A72: TC_071 | B72: 9. Analytics & Paid Subscriptions | C72: R05 | D72: Export selected leads to Excel | E72: CSV downloads with buyer contact details requirements and dates. | F72: As expected | G72: Pass
A73: TC_072 | B73: 5. Lead Management & CRM | C73: R05 | D73: Add internal private note to lead record | E73: Private note saved; visible only to seller account users. | F73: As expected | G73: Pass
A74: TC_073 | B74: 2. Seller Profile & Business Settings | C74: R05 | D74: Assign lead to sub-user (Sales Team member) | E74: Lead transferred to sub-user's dashboard view with notification. | F74: As expected | G74: Pass
A75: TC_074 | B75: 7. Mobile App & Real-Time Push | C75: R05 | D75: Check real-time Lead Push Notification | E75: Mobile push notification arrives within 5 seconds. | F75: As expected | G75: Pass
A76: TC_075 | B76: 7. Mobile App & Real-Time Push | C76: R05 | D76: Automated SMS auto-responder trigger | E76: System automatically sends customized greeting SMS to buyer. | F76: As expected | G76: Pass
A77: TC_076 | B77: 8. Security, Session & Compliance | C77: R05 | D77: Block persistent spam buyer | E77: Future inquiries from this mobile/email suppressed automatically. | F77: As expected | G77: Pass
A78: TC_077 | B78: 9. Analytics & Paid Subscriptions | C78: R05 | D78: View Lead Consumption History & analytics | E78: Graph displays leads consumed response times and conversion rates. | F78: As expected | G78: Pass
A79: TC_078 | B79: 9. Analytics & Paid Subscriptions | C79: R05 | D79: Consume location-restricted lead | E79: System blocks purchase: "Upgrade package to access leads outside region". | F79: As expected | G79: Pass
A80: TC_079 | B80: 5. Lead Management & CRM | C80: R05 | D80: Lead expiry time verification | E80: Lead becomes non-exclusive or moves to public marketplace pool. | F80: As expected | G80: Pass
A81: TC_080 | B81: 5. Lead Management & CRM | C81: R06 | D81: Search inside Lead Manager database | E81: Matching lead retrieved instantly. | F81: As expected | G81: Pass
A82: TC_081 | B82: 6. Payments, Escrow & Invoicing | C82: R06 | D82: Pay subscription fee via UPI (PhonePe/Google Pay) | E82: Payment successful; plan activated instantly; GST invoice issued. | F82: As expected | G82: Pass
...

Sheet Requirements
A1: Req ID | B1: Module Name | C1: Requirement Description | D1: Covered by Test Cases | E1: Mapped TCs | F1: Executed TCs | G1: Tested Status
A2: R01 | B2: 1. Seller Onboarding & KYC | C2: User should be able to register and verify seller account with mobile & GST | D2: TC_001 to TC_008 | E2: =COUNTIF('Test Cases'!C:C, A2) | F2: =COUNTIF('Test Cases'!C:C, A2) | G2: =IF(F2>0, "Yes", "No")
A3: R02 | B3: 2. Seller Profile & Business Settings | C3: Seller should be able to manage business profile, address, branding, and user access | D3: TC_009 to TC_025 | E3: =COUNTIF('Test Cases'!C:C, A3) | F3: =COUNTIF('Test Cases'!C:C, A3) | G3: =IF(F3>0, "Yes", "No")
A4: R03 | B4: 3. Catalog & Product Management | C4: Seller/Admin should be able to list, edit, bulk upload, and moderate catalog items | D4: TC_026 to TC_046 | E4: =COUNTIF('Test Cases'!C:C, A4) | F4: =COUNTIF('Test Cases'!C:C, A4) | G4: =IF(F4>0, "Yes", "No")
A5: R04 | B5: 4. Search, Filters & RFQ Quotes | C5: Buyers should be able to search products, apply filters, and request B2B quotes | D5: TC_047 to TC_060 | E5: =COUNTIF('Test Cases'!C:C, A5) | F5: =COUNTIF('Test Cases'!C:C, A5) | G5: =IF(F5>0, "Yes", "No")
A6: R05 | B6: 5. Lead Management & CRM | C6: Seller should receive, filter, communicate, and resolve disputes for BuyLeads | D6: TC_061 to TC_079 | E6: =COUNTIF('Test Cases'!C:C, A6) | F6: =COUNTIF('Test Cases'!C:C, A6) | G6: =IF(F6>0, "Yes", "No")
A7: R06 | B7: 6. Payments, Escrow & Invoicing | C7: System should process gateway payments, escrow, GST billing, and invoicing | D7: TC_080 to TC_090 | E7: =COUNTIF('Test Cases'!C:C, A7) | F7: =COUNTIF('Test Cases'!C:C, A7) | G7: =IF(F7>0, "Yes", "No")
A8: R07 | B8: 7. Mobile App & Real-Time Push | C8: Mobile users should receive real-time push alerts, chat, and OTP logins | D8: TC_091 to TC_099 | E8: =COUNTIF('Test Cases'!C:C, A8) | F8: =COUNTIF('Test Cases'!C:C, A8) | G8: =IF(F8>0, "Yes", "No")
A9: R08 | B9: 8. Security, Session & Compliance | C9: Platform must enforce password security, API auth, spam control, and export compliance | D9: TC_100 to TC_107 | E9: =COUNTIF('Test Cases'!C:C, A9) | F9: =COUNTIF('Test Cases'!C:C, A9) | G9: =IF(F9>0, "Yes", "No")
A10: R09 | B10: 9. Analytics & Paid Subscriptions | C10: Sellers should access analytics dashboards, package limits, and subscription plans | D10: TC_108 to TC_113 | E10: =COUNTIF('Test Cases'!C:C, A10) | F10: =COUNTIF('Test Cases'!C:C, A10) | G10: =IF(F10>0, "Yes", "No")
A11: R10 | B11: 10. Platform, UI & Performance | C11: Application must support multi-language, responsive layout, dark mode, and load SLAs | D11: TC_114 to TC_120 | E11: =COUNTIF('Test Cases'!C:C, A11) | F11: =COUNTIF('Test Cases'!C:C, A11) | G11: =IF(F11>0, "Yes", "No")
A12: R11 | B12: 6. Payments, Escrow & Invoicing | C12: Engineering release updating GST Invoicing & Lead Export with full coverage | D12: Covered in TC_080 - TC_090 | E12: =COUNTIF('Test Cases'!C:C, A12) | F12: =COUNTIF('Test Cases'!C:C, A12) | G12: =IF(F12>0, "Yes", "No")
A13: R12 | B13: 4. Search, Filters & RFQ Quotes | C13: Inquiry matching engine refactored with 160 KLOC and integration tests | D13: Covered in TC_047 - TC_060 | E13: =COUNTIF('Test Cases'!C:C, A13) | F13: =COUNTIF('Test Cases'!C:C, A13) | G13: =IF(F13>0, "Yes", "No")
... A15: R14 | B15: 7. Mobile App & Real-Time Push | C15: Push notification server latency verification under peak load runs | D15: Covered in TC_091 - TC_099 | E15: =COUNTIF('Test Cases'!C:C, A15) | F15: =COUNTIF('Test Cases'!C:C, A15) | G15: =IF(F15>0, "Yes", "No")

Sheet Defects
A1: Defect ID | B1: Module Name | C1: Failed TCs Count | D1: Defect Summary & Reproduction Steps | E1: Severity | F1: Defect Status
A2: DEF-001 | B2: 3. Catalog & Product Management | C2: 1 | D2: Product approval workflow fails to flag banned/prohibited keywords in admin moderation. Steps: 1. Add product with banned keywords -> 2. Submit -> 3. Product approved without flag. | E2: High | F2: Open
A3: DEF-002 | B3: 5. Lead Management & CRM | C3: 1 | D3: Claim BuyLead refund fails to verify/refund points for fake contact details. Steps: 1. Report lead with non-working phone -> 2. Verify refund log -> 3. Credit points not restored. | E3: High | F3: Open

Sheet Response Times
A1: Test Run #
A2: Test Run 1 | B2: 3.2
A3: Test Run 2 | B3: 1.8
A4: Test Run 3 | B4: 4.5
A5: Test Run 4 | B5: 2.1
A6: Test Run 5 | B6: 2.8
